Workbook

Sheet Dataset
A1: S/N | B1: Staff ID | C1: Staff Name | D1: First Name | E1: Last Name | F1: Divison | G1: Department | H1: Job Role | I1: Gender | J1: Date of Birth | K1: Age | L1: Age Range | M1: Employment Date | N1: Length of Stay (LOS) | O1: LOS Range | P1: Location | Q1: Grade | R1: Basic Salary | S1: Performance Score
A2: 1 | B2: AN00001 | C2: Abayomi,Sunday | D2: Abayomi | E2: Sunday | F2: APP | G2: Plant & Maintenance | H2: Manufacturing Team Lead | I2: Female | J2: 04-12-1988 | K2: =ROUNDDOWN((TODAY()-J2)/365,0) -> 37 | L2: =_xlfn.XLOOKUP(K2,'Age Range'!A:A,'Age Range'!B:B) -> 30-39 | M2: 10-15-2003 | N2: =ROUNDDOWN((TODAY()-M2)/365,0) -> 22 | O2: =_xlfn.XLOOKUP(N2,'LOS Range'!A:A,'LOS Range'!B:B) -> Above 20 years | P2: Ogun | Q2: Graduate Trainee | R2: 186944.06 | S2: 90
A3: 2 | B3: AN00002 | C3: Abdul-Kareem,Folake | D3: Abdul-Kareem | E3: Folake | F3: PAN | G3: Plant & Maintenance | H3: Filling Line Team Lead | I3: Male | J3: 08-29-1972 | K3: =ROUNDDOWN((TODAY()-J3)/365,0) -> 53 | L3: =_xlfn.XLOOKUP(K3,'Age Range'!A:A,'Age Range'!B:B) -> 50-55 | M3: 01-02-2002 | N3: =ROUNDDOWN((TODAY()-M3)/365,0) -> 24 | O3: =_xlfn.XLOOKUP(N3,'LOS Range'!A:A,'LOS Range'!B:B) -> Above 20 years | P3: Oyo | Q3: Graduate Trainee | R3: 186729.58 | S3: 91
A4: 3 | B4: AN00003 | C4: Abdulwahab,Olawale | D4: Abdulwahab | E4: Olawale | F4: APP | G4: Plant & Maintenance | H4: Inplant Team Lead | I4: Male | J4: 10-31-1991 | K4: =ROUNDDOWN((TODAY()-J4)/365,0) -> 34 | L4: =_xlfn.XLOOKUP(K4,'Age Range'!A:A,'Age Range'!B:B) -> 30-39 | M4: 04-26-2004 | N4: =ROUNDDOWN((TODAY()-M4)/365,0) -> 21 | O4: =_xlfn.XLOOKUP(N4,'LOS Range'!A:A,'LOS Range'!B:B) -> Above 20 years | P4: Lagos | Q4: Graduate Trainee | R4: 184575.22 | S4: 92
A5: 4 | B5: AN00004 | C5: Abegunrin,Dare | D5: Abegunrin | E5: Dare | F5: APP | G5: Sales | H5: Sales Executive | I5: Male | J5: 11-18-1987 | K5: =ROUNDDOWN((TODAY()-J5)/365,0) -> 38 | L5: =_xlfn.XLOOKUP(K5,'Age Range'!A:A,'Age Range'!B:B) -> 30-39 | M5: 03-09-2009 | N5: =ROUNDDOWN((TODAY()-M5)/365,0) -> 16 | O5: =_xlfn.XLOOKUP(N5,'LOS Range'!A:A,'LOS Range'!B:B) -> 15 - 19 years | P5: Lagos | Q5: Graduate Trainee | R5: 138336.3 | S5: 93
A6: 5 | B6: AN00005 | C6: Abiodun-Afolabi,Fadekemi | D6: Abiodun-Afolabi | E6: Fadekemi | F6: APP | G6: Sales | H6: Machine Operator | I6: Male | J6: 08-18-1983 | K6: =ROUNDDOWN((TODAY()-J6)/365,0) -> 42 | L6: =_xlfn.XLOOKUP(K6,'Age Range'!A:A,'Age Range'!B:B) -> 40-49 | M6: 05-02-1997 | N6: =ROUNDDOWN((TODAY()-M6)/365,0) -> 28 | O6: =_xlfn.XLOOKUP(N6,'LOS Range'!A:A,'LOS Range'!B:B) -> Above 20 years | P6: Lagos | Q6: Graduate Trainee | R6: 177205.62 | S6: 94
A7: 6 | B7: AN00006 | C7: Abiola,Babatunde | D7: Abiola | E7: Babatunde | F7: CSC | G7: Design | H7: Colour Consultant | I7: Male | J7: 11-02-1984 | K7: =ROUNDDOWN((TODAY()-J7)/365,0) -> 41 | L7: =_xlfn.XLOOKUP(K7,'Age Range'!A:A,'Age Range'!B:B) -> 40-49 | M7: 03-09-2009 | N7: =ROUNDDOWN((TODAY()-M7)/365,0) -> 16 | O7: =_xlfn.XLOOKUP(N7,'LOS Range'!A:A,'LOS Range'!B:B) -> 15 - 19 years | P7: Lagos | Q7: Graduate Trainee | R7: 141339.48 | S7: 95
A8: 7 | B8: AN00007 | C8: Abiri,Olayinka | D8: Abiri | E8: Olayinka | F8: CSC | G8: Design | H8: Colour Consultant | I8: Male | J8: 08-20-1992 | K8: =ROUNDDOWN((TODAY()-J8)/365,0) -> 33 | L8: =_xlfn.XLOOKUP(K8,'Age Range'!A:A,'Age Range'!B:B) -> 30-39 | M8: 03-09-2009 | N8: =ROUNDDOWN((TODAY()-M8)/365,0) -> 16 | O8: =_xlfn.XLOOKUP(N8,'LOS Range'!A:A,'LOS Range'!B:B) -> 15 - 19 years | P8: Enugu | Q8: Graduate Trainee | R8: 262557.04 | S8: 80
A9: 8 | B9: AN00008 | C9: Abisoye,Zachius | D9: Abisoye | E9: Zachius | F9: CSC | G9: Designs | H9: Colour Consultant | I9: Female | J9: 02-01-1989 | K9: =ROUNDDOWN((TODAY()-J9)/365,0) -> 36 | L9: =_xlfn.XLOOKUP(K9,'Age Range'!A:A,'Age Range'!B:B) -> 30-39 | M9: 06-02-2008 | N9: =ROUNDDOWN((TODAY()-M9)/365,0) -> 17 | O9: =_xlfn.XLOOKUP(N9,'LOS Range'!A:A,'LOS Range'!B:B) -> 15 - 19 years | P9: Lagos | Q9: Graduate Trainee | R9: 165517.98 | S9: 81
A10: 9 | B10: AN00009 | C10: Adebanjo,Kemi | D10: Adebanjo | E10: Kemi | F10: APP | G10: Sales | H10: Sales Executive | I10: Female | J10: 11-18-1987 | K10: =ROUNDDOWN((TODAY()-J10)/365,0) -> 38 | L10: =_xlfn.XLOOKUP(K10,'Age Range'!A:A,'Age Range'!B:B) -> 30-39 | M10: 09-01-2008 | N10: =ROUNDDOWN((TODAY()-M10)/365,0) -> 17 | O10: =_xlfn.XLOOKUP(N10,'LOS Range'!A:A,'LOS Range'!B:B) -> 15 - 19 years | P10: Abuja | Q10: Graduate Trainee | R10: 262557.06 | S10: 82
A11: 10 | B11: AN00010 | C11: Adegbite,James | D11: Adegbite | E11: James | F11: APP | G11: Sales | H11: Sales Executive | I11: Female | J11: 03-13-1995 | K11: =ROUNDDOWN((TODAY()-J11)/365,0) -> 30 | L11: =_xlfn.XLOOKUP(K11,'Age Range'!A:A,'Age Range'!B:B) -> 30-39 | M11: 01-02-2002 | N11: =ROUNDDOWN((TODAY()-M11)/365,0) -> 24 | O11: =_xlfn.XLOOKUP(N11,'LOS Range'!A:A,'LOS Range'!B:B) -> Above 20 years | P11: Lagos | Q11: Graduate Trainee | R11: 180321.22 | S11: 83
A12: 11 | B12: AN00011 | C12: Adegbola,Idowu | D12: Adegbola | E12: Idowu | F12: APP | G12: Sales | H12: Sales Executive | I12: Female | J12: 02-28-1988 | K12: =ROUNDDOWN((TODAY()-J12)/365,0) -> 37 | L12: =_xlfn.XLOOKUP(K12,'Age Range'!A:A,'Age Range'!B:B) -> 30-39 | M12: 03-09-2009 | N12: =ROUNDDOWN((TODAY()-M12)/365,0) -> 16 | O12: =_xlfn.XLOOKUP(N12,'LOS Range'!A:A,'LOS Range'!B:B) -> 15 - 19 years | P12: Lagos | Q12: Graduate Trainee | R12: 198454.06 | S12: 84
A13: 12 | B13: AN00012 | C13: Adegoke,Joseph | D13: Adegoke | E13: Joseph | F13: APP | G13: Sales | H13: Sales Executive | I13: Female | J13: 03-11-1989 | K13: =ROUNDDOWN((TODAY()-J13)/365,0) -> 36 | L13: =_xlfn.XLOOKUP(K13,'Age Range'!A:A,'Age Range'!B:B) -> 30-39 | M13: 03-08-2004 | N13: =ROUNDDOWN((TODAY()-M13)/365,0) -> 21 | O13: =_xlfn.XLOOKUP(N13,'LOS Range'!A:A,'LOS Range'!B:B) -> Above 20 years | P13: Delta | Q13: Graduate Trainee | R13: 150744.38 | S13: 85
... A240: 239 | B240: AN00239 | C240: Koro,Mutour | D240: Koro | E240: Mutour | F240: PAN | G240: Sales | H240: Key Accounts Manager (T3) | I240: Male | J240: 10-28-1982 | K240: =ROUNDDOWN((TODAY()-J240)/365,0) -> 43 | L240: =_xlfn.XLOOKUP(K240,'Age Range'!A:A,'Age Range'!B:B) -> 40-49 | M240: 05-01-2021 | N240: =ROUNDDOWN((TODAY()-M240)/365,0) -> 4 | O240: =_xlfn.XLOOKUP(N240,'LOS Range'!A:A,'LOS Range'!B:B) -> 2 - 4 years | P240: Oyo | Q240: Graduate Trainee | R240: 129860.25 | S240: 54

Sheet Recruitment
A1: SN | B1: Recruitment ID | C1: Full Name | D1: Sourcing Date | E1: Offer Extension Date | F1: TTO | G1: Employment Date | H1: Department | I1: Source | J1: Designation | K1: Grade | L1: Type
A2: 1 | B2: RCID00001 | C2: Adedoyin Adegoju Enitan | D2: 44596 | E2: 44639 | F2: 6.1428571 | G2: 44655 | H2: Plant & Maintenance | I2: Internal | J2: Manufacturing Team Lead | K2: Graduate Trainee | L2: Replacement
A3: 2 | B3: RCID00002 | C3: Femi Ayebameru Joseph | D3: 44452 | E3: 44627 | F3: 25 | G3: 44655 | H3: Plant & Maintenance | I3: Internal | J3: Filling Line Team Lead | K3: Graduate Trainee | L3: Replacement
A4: 3 | B4: RCID00003 | C4: Arisa Ikechukwu Godson | D4: 44452 | E4: 44627 | F4: 25 | G4: 44655 | H4: Plant & Maintenance | I4: Internal | J4: Inplant Team Lead | K4: Graduate Trainee | L4: Replacement
A5: 4 | B5: RCID00004 | C5: Obikanye Olushola | D5: 44573 | E5: 44634 | F5: 8.7142857 | G5: 44655 | H5: Sales | I5: External | J5: Sales Executive | K5: Graduate Trainee | L5: Replacement
A6: 5 | B6: RCID00005 | C6: Adekoya Olajumoke | D6: 44580 | E6: 44621 | F6: 5.8571429 | G6: 44655 | H6: Sales | I6: External | J6: Machine Operator | K6: Graduate Trainee | L6: Replacement
A7: 6 | B7: RCID00006 | C7: Olapeju Ibekwe Sinmisola | D7: 44487 | E7: 44617 | F7: 18.571429 | G7: 44655 | H7: Design | I7: External | J7: Colour Consultant | K7: Graduate Trainee | L7: Replacement
A8: 7 | B8: RCID00007 | C8: Awa Nnenna | D8: 44573 | E8: 44634 | F8: 8.7142857 | G8: 44655 | H8: Design | I8: Internal | J8: Colour Consultant | K8: Experienced Officer | L8: Replacement
A9: 8 | B9: RCID00008 | C9: Ruth Ozigbo Omojo | D9: 44573 | E9: 44634 | F9: 8.7142857 | G9: 44655 | H9: Design | I9: Internal | J9: Colour Consultant | K9: Experienced Officer | L9: New Hire
A10: 9 | B10: RCID00009 | C10: Chidimma Okoli Ijeoma | D10: 44573 | E10: 44634 | F10: 8.7142857 | G10: 44655 | H10: Sales | I10: Internal | J10: Sales Executive | K10: Experienced Officer | L10: New Hire
A11: 10 | B11: RCID00010 | C11: Ibidapo Martins Afolabi | D11: 44525 | E11: 44627 | F11: 14.571429 | G11: 44655 | H11: Sales | I11: External | J11: Sales Executive | K11: Experienced Officer | L11: New Hire
A12: 11 | B12: RCID00011 | C12: Ademola Adesina | D12: 44573 | E12: 44634 | F12: 8.7142857 | G12: 44669 | H12: Sales | I12: External | J12: Sales Executive | K12: Experienced Officer | L12: New Hire
A13: 12 | B13: RCID00012 | C13: Abiola Akerele Oluwasegun | D13: 44565 | E13: 44655 | F13: 12.857143 | G13: 44669 | H13: Sales | I13: External | J13: Sales Executive | K13: Experienced Officer | L13: New Hire
... A51: 50 | B51: RCID00050 | C51: Bilikis Oseni Olasunkanmi | D51: 44771 | E51: 44824 | F51: 7.5714286 | G51: 44838 | H51: Finance | I51: Internal | J51: Bank Reconciliation Officer | K51: Manager | L51: New Hire

Sheet Exit
A1: S/N | B1: EmployeeID | C1: Personnel Name | D1: Division | E1: Department | F1: Job Role | G1: Work Model | H1: Gender | I1: Date of Birth | J1: Age | K1: Age Range | L1: Employment Date | M1: Exit Date | N1: Length of Stay (LOS) | O1: LOS Range | P1: Graduate Trainee | Q1: Cadre | R1: Performance Score | S1: Talent Segmentation | T1: Basic salary | U1: Gross Pay | V1: Destination | W1: Destination_Type
A2: 1 | B2: AN00001 | C2: Abayomi, Fatai Sunday | D2: APP | E2: Plant & Maintenance | F2: Manufacturing Team Lead | G2: Onsite | H2: Female | I2: =VLOOKUP(B:B,Dataset!B:J,8,) -> Female | L2: 37909 | M2: 44829 | P2: Graduate Trainee | R2: 90 | T2: 747776.22 | U2: =VLOOKUP(Exit!B:B,Dataset!B:S,21,) -> #REF! | V2: Canada | W2: Relocation
A3: 2 | B3: AN00005 | C3: Abiodun-Afolabi, Fadekemi | D3: APP | E3: Sales | F3: Machine Operator | G3: Onsite | H3: Male | I3: =VLOOKUP(B:B,Dataset!B:J,8,) -> Male | L3: 35552 | M3: 44759 | P3: Graduate Trainee | R3: 94 | T3: 708822.47 | U3: =VLOOKUP(Exit!B:B,Dataset!B:S,21,) -> #REF! | V3: Canada | W3: Relocation
A4: 3 | B4: AN00010 | C4: Adegbite, Adesola James | D4: APP | E4: Sales | F4: Sales Executive | G4: Hybrid | H4: Female | I4: =VLOOKUP(B:B,Dataset!B:J,8,) -> Female | L4: 37258 | M4: 44804 | P4: Graduate Trainee | R4: 83 | T4: 721284.9 | U4: =VLOOKUP(Exit!B:B,Dataset!B:S,21,) -> #REF! | V4: Canada | W4: Relocation
A5: 4 | B5: AN00015 | C5: Adejumo, Ganiyu Adetunji | D5: APP | E5: Sales | F5: Sales Executive | G5: Hybrid | H5: Female | I5: =VLOOKUP(B:B,Dataset!B:J,8,) -> Female | L5: 40238 | M5: 44715 | P5: Graduate Trainee | R5: 72 | T5: 793816.25 | U5: =VLOOKUP(Exit!B:B,Dataset!B:S,21,) -> #REF! | V5: Canada | W5: Relocation
A6: 5 | B6: AN00020 | C6: Adeniyi, Babatunde | D6: APP | E6: Sales | F6: Sales Executive | G6: Hybrid | H6: Female | I6: =VLOOKUP(B:B,Dataset!B:J,8,) -> Female | L6: 40339 | M6: 44687 | P6: Graduate Trainee | R6: 61 | T6: 566886.93 | U6: =VLOOKUP(Exit!B:B,Dataset!B:S,21,) -> #REF! | V6: United Kingdom | W6: Relocation
A7: 6 | B7: AN00025 | C7: Adesogbon, Abiola | D7: CSC | E7: Design | F7: Colour Consultant | G7: Remote | H7: Male | I7: =VLOOKUP(B:B,Dataset!B:J,8,) -> Male | L7: 38055 | M7: 44711 | P7: Graduate Trainee | R7: 50 | T7: 660124.11 | U7: =VLOOKUP(Exit!B:B,Dataset!B:S,21,) -> #REF! | V7: United Kingdom | W7: Relocation
A8: 7 | B8: AN00030 | C8: Adewunmi, Samuel Olugbenga | D8: APP | E8: Sales | F8: Machine Operator | G8: Onsite | H8: Female | I8: =VLOOKUP(B:B,Dataset!B:J,8,) -> Female | L8: 41232 | M8: 44820 | P8: Graduate Trainee | R8: 55 | T8: 939182.04 | U8: =VLOOKUP(Exit!B:B,Dataset!B:S,21,) -> #REF! | V8: United Kingdom | W8: Relocation
A9: 8 | B9: AN00035 | C9: Afe, Samuel Oluwatoyin | D9: APP | E9: Technical | F9: PI & ISO Specialist | G9: Remote | H9: Male | I9: =VLOOKUP(B:B,Dataset!B:J,8,) -> Male | L9: 41290 | M9: 44813 | P9: Graduate Trainee | R9: 44 | T9: 681496.8 | U9: =VLOOKUP(Exit!B:B,Dataset!B:S,21,) -> #REF! | V9: United Kingdom | W9: Relocation
A10: 9 | B10: AN00040 | C10: Agbeyomi, Akinjide | D10: APP | E10: Technical | F10: Raw Material Analyst | G10: Onsite | H10: Female | I10: =VLOOKUP(B:B,Dataset!B:J,8,) -> Female | L10: 39664 | M10: 44827 | P10: Graduate Trainee | R10: 33 | T10: 690901.12 | U10: =VLOOKUP(Exit!B:B,Dataset!B:S,21,) -> #REF! | V10: UG Bank | W10: Local
A11: 10 | B11: AN00045 | C11: Ajala, Olusegun Rufus | D11: PAN | E11: Technical | F11: Chemist - Solvent Based | G11: Onsite | H11: Male | I11: =VLOOKUP(B:B,Dataset!B:J,8,) -> Male | L11: 38504 | M11: 44831 | P11: Graduate Trainee | R11: 92 | T11: 1621826.3 | U11: =VLOOKUP(Exit!B:B,Dataset!B:S,21,) -> #REF! | V11: AB Finance | W11: Local
A12: 11 | B12: AN00050 | C12: Akano, Ibukun Smart | D12: PAN | E12: Finance | F12: Bank Reconciliation Officer | G12: Hybrid | H12: Female | I12: =VLOOKUP(B:B,Dataset!B:J,8,) -> Female | L12: 39678 | M12: 44717 | P12: Graduate Trainee | R12: 81 | T12: 1299083 | U12: =VLOOKUP(Exit!B:B,Dataset!B:S,21,) -> #REF! | V12: AB Finance | W12: Local
A13: 12 | B13: AN00055 | C13: Akinseesin, Ebenezer Olatunji | D13: APP | E13: Sales | F13: Sales Executive | G13: Hybrid | H13: Male | I13: =VLOOKUP(B:B,Dataset!B:J,8,) -> Male | L13: 40878 | M13: 44776 | P13: Graduate Trainee | R13: 70 | T13: 592484.97 | U13: =VLOOKUP(Exit!B:B,Dataset!B:S,21,) -> #REF! | V13: AB Finance | W13: Local
... A48: 47 | B48: AN00230 | C48: Olabisi, Oyebisi | D48: PAN | E48: FINANCE | F48: Financial Accountant | G48: Remote | H48: Male | I48: =VLOOKUP(B:B,Dataset!B:J,8,) -> Male | L48: 44270 | M48: 44668 | P48: Graduate Trainee | R48: 61 | T48: 3538293 | U48: =VLOOKUP(Exit!B:B,Dataset!B:S,21,) -> #REF! | V48: United States of America | W48: Relocation
A49: 48 | B49: AN00235 | C49: Esan, Ifetobi Emmanuel | D49: PAN | E49: SALES | F49: Key Accounts Manager (T3) | G49: Hybrid | H49: Male | I49: =VLOOKUP(B:B,Dataset!B:J,8,) -> Male | L49: 44317 | M49: 44682 | P49: =VLOOKUP(B:B,Dataset!B:Q,15,) -> Lagos | R49: 50 | T49: 736674 | U49: =VLOOKUP(Exit!B:B,Dataset!B:S,21,) -> #REF! | V49: United States of America | W49: Relocation

Sheet Classification Legend
B2: Age | C2: Age Range | E2: State | F2: Zone | H2: LOS | I2: Range | K2: Business Unit | L2: Category | N2: Grade | O2: Cadre | Q2: Job Roles | R2: Work Model | T2: Performance Score | U2: Talent Segmentation
B3: 11 | C3: School Leavers | E3: Benue | F3: North Central | H3: 0 | I3: 0 - 1 year | K3: Plant & Maintenance | L3: Operations | N3: Graduate Trainee | O3: Junior Mgt | Q3: Accounts Payable & Payroll Supv | R3: Remote | T3: 0 | U3: Poor
B4: 12 | C4: School Leavers | E4: Abuja | F4: North Central | H4: 1 | I4: 0 - 1 year | K4: Sales | L4: Commercial | N4: Graduate Trainee | O4: Junior Mgt | Q4: Accounts Payable Officer | R4: Remote | T4: 1 | U4: Poor
B5: 13 | C5: School Leavers | E5: Kogi | F5: North Central | H5: 2 | I5: 2 - 4 years | K5: Design | L5: Enablers | N5: Graduate Trainee | O5: Junior Mgt | Q5: Admin & Facilities Coordinator | R5: Onsite | T5: 2 | U5: Poor
B6: 14 | C6: School Leavers | E6: Kwara | F6: North Central | H6: 3 | I6: 2 - 4 years | K6: Supply Chain | L6: Commercial | N6: Graduate Trainee | O6: Junior Mgt | Q6: Assistant Brand Manager | R6: Remote | T6: 3 | U6: Poor
B7: 15 | C7: School Leavers | E7: Nasarawa | F7: North Central | H7: 4 | I7: 2 - 4 years | K7: Technical | L7: Enablers | N7: Graduate Trainee | O7: Junior Mgt | Q7: Asst Production Scheduler | R7: Hybrid | T7: 4 | U7: Poor
B8: 16 | C8: School Leavers | E8: Niger | F8: North Central | H8: 5 | I8: 5 - 9 years | K8: Finance | L8: Operations | N8: Experienced Officer | O8: Middle Mgt | Q8: Asst. Retail Expansion Manager | R8: Hybrid | T8: 5 | U8: Poor
B9: 17 | C9: School Leavers | E9: Plateau | F9: North Central | H9: 6 | I9: 5 - 9 years | K9: Information Technology | L9: Enablers | N9: Experienced Officer | O9: Middle Mgt | Q9: Bank Reconciliation Officer | R9: Hybrid | T9: 6 | U9: Poor
B10: 18 | C10: School Leavers | E10: Adamawa | F10: North East | H10: 7 | I10: 5 - 9 years | K10: Marketing | L10: Commercial | N10: Experienced Officer | O10: Middle Mgt | Q10: Brand Manager | R10: Hybrid | T10: 7 | U10: Poor
B11: 19 | C11: School Leavers | E11: Bauchi | F11: North East | H11: 8 | I11: 5 - 9 years | K11: Capability Development | L11: Operations | N11: Experienced Officer | O11: Middle Mgt | Q11: Business Development Manager | R11: Hybrid | T11: 8 | U11: Poor
B12: 20 | C12: 20-29 | E12: Borno | F12: North East | H12: 9 | I12: 5 - 9 years | K12: Human Resources | L12: Enablers | N12: Experienced Officer | O12: Middle Mgt | Q12: Callover Officer | R12: Hybrid | T12: 9 | U12: Poor
B13: 21 | C13: 20-29 | E13: Gombe | F13: North East | H13: 10 | I13: 10 - 14 years | K13: R&C | L13: Operations | N13: Manager | O13: Senior Mgt | Q13: Capability Development Manager | R13: Remote | T13: 10 | U13: Poor
B14: 22 | C14: 20-29 | E14: Taraba | F14: North East | H14: 11 | I14: 10 - 14 years | K14: Communications | L14: Enablers | N14: Manager | O14: Senior Mgt | Q14: Careline Rep | R14: Onsite | T14: 11 | U14: Poor
... B16: 24 | C16: 20-29 | E16: Kaduna | F16: North West | H16: 13 | I16: 10 - 14 years | K16: MD'S Office | L16: Enablers | N16: Manager | O16: Senior Mgt | Q16: Chemist - Water Based | R16: Onsite | T16: 13 | U16: Poor
B17: 25 | C17: 20-29 | E17: Katsina | F17: North West | H17: 14 | I17: 10 - 14 years | N17: Manager | O17: Senior Mgt | Q17: Chief Commercial Officer | R17: Hybrid | T17: 14 | U17: Poor
B18: 26 | C18: 20-29 | E18: Kano | F18: North West | H18: 15 | I18: 15 - 19 years | N18: Anciliary Officer | O18: Foremen | Q18: Cleaning/ETP Operator | R18: Onsite | T18: 15 | U18: Poor
B19: 27 | C19: 20-29 | E19: Kebbi | F19: North West | H19: 16 | I19: 15 - 19 years | N19: Anciliary Officer | O19: Foremen | Q19: Colour Consultant | R19: Remote | T19: 16 | U19: Poor
B20: 28 | C20: 20-29 | E20: Sokoto | F20: North West | H20: 17 | I20: 15 - 19 years | N20: Anciliary Officer | O20: Foremen | Q20: Colour Matcher | R20: Remote | T20: 17 | U20: Poor
B21: 29 | C21: 20-29 | E21: Jigawa | F21: North West | H21: 18 | I21: 15 - 19 years | N21: Anciliary Officer | O21: Foremen | Q21: Colour Matching Team Lead | R21: Remote | T21: 18 | U21: Poor
B22: 30 | C22: 30-39 | E22: Zamfara | F22: North West | H22: 19 | I22: 15 - 19 years | N22: Anciliary Officer | O22: Foremen | Q22: Company Sec & Gen Counsel | R22: Hybrid | T22: 19 | U22: Poor
B23: 31 | C23: 30-39 | E23: Abia | F23: South East | H23: 20 | I23: Above 20 years | Q23: Cost Accountant | R23: Remote | T23: 20 | U23: Poor
B24: 32 | C24: 30-39 | E24: Anambra | F24: South East | H24: 21 | I24: Above 20 years | Q24: Credit Control & Insurance Supervisor | R24: Remote | T24: 21 | U24: Poor
B25: 33 | C25: 30-39 | E25: Ebonyi | F25: South East | H25: 22 | I25: Above 20 years | Q25: Development Lead | R25: Remote | T25: 22 | U25: Poor
B26: 34 | C26: 30-39 | E26: Enugu | F26: South East | H26: 23 | I26: Above 20 years | Q26: Digital Brand /Media Manager | R26: Remote | T26: 23 | U26: Poor
B27: 35 | C27: 30-39 | E27: Imo | F27: South East | H27: 24 | I27: Above 20 years | Q27: Digital Tech & Security Lead | R27: Remote | T27: 24 | U27: Poor
B28: 36 | C28: 30-39 | E28: Akwa-Ibom | F28: South South | H28: 25 | I28: Above 20 years | Q28: Dispatch Officer | R28: Onsite | T28: 25 | U28: Poor
B29: 37 | C29: 30-39 | E29: Bayelsa | F29: South South | H29: 26 | I29: Above 20 years | Q29: Distr & WH Coordinator | R29: Onsite | T29: 26 | U29: Poor
B30: 38 | C30: 30-39 | E30: Cross-River | F30: South South | H30: 27 | I30: Above 20 years | Q30: Distr & WH Lead | R30: Onsite | T30: 27 | U30: Poor
B31: 39 | C31: 30-39 | E31: Delta | F31: South South | H31: 28 | I31: Above 20 years | Q31: Distr & WH Supervisor, Oregun | R31: Onsite | T31: 28 | U31: Poor
B32: 40 | C32: 40-49 | E32: Edo | F32: South South | H32: 29 | I32: Above 20 years | Q32: Executive Assistant to MD | R32: Hybrid | T32: 29 | U32: Poor
B33: 41 | C33: 40-49 | E33: Rivers | F33: South South | H33: 30 | I33: Above 20 years | Q33: Factory Tech | R33: Onsite | T33: 30 | U33: Mediocre
B34: 42 | C34: 40-49 | E34: Ekiti | F34: South West | Q34: Filling Line Team Lead | R34: Onsite | T34: 31 | U34: Mediocre
B35: 43 | C35: 40-49 | E35: Lagos | F35: South West | K35: Plant & Maintenance | Q35: Filling Operative | R35: Onsite | T35: 32 | U35: Mediocre
B36: 44 | C36: 40-49 | E36: Osun | F36: South West | K36: Sales | Q36: Finance Controller | R36: Remote | T36: 33 | U36: Mediocre
B37: 45 | C37: 40-49 | E37: Ondo | F37: South West | K37: Design | Q37: Financial Accountant | R37: Remote | T37: 34 | U37: Mediocre
B38: 46 | C38: 40-49 | E38: Ogun | F38: South West | K38: Supply Chain | Q38: Financial Planning & Analysis Manager | R38: Remote | T38: 35 | U38: Mediocre
B39: 47 | C39: 40-49 | E39: Oyo | F39: South West | K39: Technical | Q39: Finished Goods Analyst | R39: Onsite | T39: 36 | U39: Mediocre
B40: 48 | C40: 40-49 | K40: Finance | Q40: Finished Goods Chemist | R40: Onsite | T40: 37 | U40: Mediocre
B41: 49 | C41: 40-49 | K41: Information Technology | Q41: Fixed Assets & Tax Supervisor | R41: Remote | T41: 38 | U41: Mediocre
B42: 50 | C42: 50-55 | K42: Marketing | Q42: Head of Marketing | R42: Remote | T42: 39 | U42: Mediocre
...

Sheet Performace Score
A1: Performance Score | B1: Talent Segmentation
A2: 0 | B2: Poor
A3: 1 | B3: Poor
A4: 2 | B4: Poor
A5: 3 | B5: Poor
A6: 4 | B6: Poor
A7: 5 | B7: Poor
A8: 6 | B8: Poor
A9: 7 | B9: Poor
A10: 8 | B10: Poor
A11: 9 | B11: Poor
A12: 10 | B12: Poor
A13: 11 | B13: Poor
... A102: 100 | B102: Hi-po

Sheet Work Model
A1: Job Roles | B1: Work Model
A2: Accounts Payable & Payroll Supv | B2: Remote
A3: Accounts Payable Officer | B3: Remote
A4: Admin & Facilities Coordinator | B4: Onsite
A5: Assistant Brand Manager | B5: Remote
A6: Asst Production Scheduler | B6: Hybrid
A7: Asst. Retail Expansion Manager | B7: Hybrid
A8: Bank Reconciliation Officer | B8: Hybrid
A9: Brand Manager | B9: Hybrid
A10: Business Development Manager | B10: Hybrid
A11: Callover Officer | B11: Hybrid
A12: Capability Development Manager | B12: Remote
... A101: WH Supervisor, GG | B101: Onsite

Sheet LOS Range
A1: LOS | B1: Range
A2: 0 | B2: 0 - 1 year
A3: 1 | B3: 0 - 1 year
A4: 2 | B4: 2 - 4 years
A5: 3 | B5: 2 - 4 years
A6: 4 | B6: 2 - 4 years
A7: 5 | B7: 5 - 9 years
A8: 6 | B8: 5 - 9 years
A9: 7 | B9: 5 - 9 years
A10: 8 | B10: 5 - 9 years
A11: 9 | B11: 5 - 9 years
A12: 10 | B12: 10 - 14 years
A13: 11 | B13: 10 - 14 years
... A32: 30 | B32: Above 20 years

Sheet Age Range
A2: Age | B2: Age Range
A3: 11 | B3: School Leavers
A4: 12 | B4: School Leavers
A5: 13 | B5: School Leavers
A6: 14 | B6: School Leavers
A7: 15 | B7: School Leavers
A8: 16 | B8: School Leavers
A9: 17 | B9: School Leavers
A10: 18 | B10: School Leavers
A11: 19 | B11: School Leavers
A12: 20 | B12: 20-29
A13: 21 | B13: 20-29
A14: 22 | B14: 20-29
... A57: 63 | B57: 56-70

Sheet Task-Solution
A1: Number of Employees | C1: Department | D1: Count of Employees | E1: Average Salary | H1: Age | I1: Age Range
A2: =COUNT(Dataset!A:A) -> 239 | C2: Plant & Maintenance | D2: =COUNTIF(Dataset!G:G,'Task-Solution'!C2) -> 31 | E2: =AVERAGEIF(Dataset!G:G,'Task-Solution'!C2,Dataset!R:R) -> 329846.68 | H2: =ROUNDDOWN((TODAY()-Dataset!J2)/365,0) -> 37 | I2: =_xlfn.XLOOKUP(H2,'Age Range'!A:A,'Age Range'!B:B) -> 30-39
C3: Sales | D3: =COUNTIF(Dataset!G:G,'Task-Solution'!C3) -> 112 | E3: =AVERAGEIF(Dataset!G:G,'Task-Solution'!C3,Dataset!R:R) -> 413596.37 | H3: =ROUNDDOWN((TODAY()-Dataset!J3)/365,0) -> 53 | I3: =_xlfn.XLOOKUP(H3,'Age Range'!A:A,'Age Range'!B:B) -> 50-55
A4: Average Age of Employees | C4: Design | D4: =COUNTIF(Dataset!G:G,'Task-Solution'!C4) -> 20 | E4: =AVERAGEIF(Dataset!G:G,'Task-Solution'!C4,Dataset!R:R) -> 248870.49 | H4: =ROUNDDOWN((TODAY()-Dataset!J4)/365,0) -> 34 | I4: =_xlfn.XLOOKUP(H4,'Age Range'!A:A,'Age Range'!B:B) -> 30-39
A5: =AVERAGE(Dataset!K:K) -> 35.631799 | C5: Supply Chain | D5: =COUNTIF(Dataset!G:G,'Task-Solution'!C5) -> 22 | E5: =AVERAGEIF(Dataset!G:G,'Task-Solution'!C5,Dataset!R:R) -> 455333.97 | H5: =ROUNDDOWN((TODAY()-Dataset!J5)/365,0) -> 38 | I5: =_xlfn.XLOOKUP(H5,'Age Range'!A:A,'Age Range'!B:B) -> 30-39
C6: Technical | D6: =COUNTIF(Dataset!G:G,'Task-Solution'!C6) -> 19 | E6: =AVERAGEIF(Dataset!G:G,'Task-Solution'!C6,Dataset!R:R) -> 388866.11 | H6: =ROUNDDOWN((TODAY()-Dataset!J6)/365,0) -> 42 | I6: =_xlfn.XLOOKUP(H6,'Age Range'!A:A,'Age Range'!B:B) -> 40-49
A7: Total Salaries | C7: Finance | D7: =COUNTIF(Dataset!G:G,'Task-Solution'!C7) -> 11 | E7: =AVERAGEIF(Dataset!G:G,'Task-Solution'!C7,Dataset!R:R) -> 979924.99 | H7: =ROUNDDOWN((TODAY()-Dataset!J7)/365,0) -> 41 | I7: =_xlfn.XLOOKUP(H7,'Age Range'!A:A,'Age Range'!B:B) -> 40-49
A8: =SUM(Dataset!R:R) -> 1.1723416e+08 | C8: Information Technology | D8: =COUNTIF(Dataset!G:G,'Task-Solution'!C8) -> 5 | E8: =AVERAGEIF(Dataset!G:G,'Task-Solution'!C8,Dataset!R:R) -> 524321.3 | H8: =ROUNDDOWN((TODAY()-Dataset!J8)/365,0) -> 33 | I8: =_xlfn.XLOOKUP(H8,'Age Range'!A:A,'Age Range'!B:B) -> 30-39
C9: Marketing | D9: =COUNTIF(Dataset!G:G,'Task-Solution'!C9) -> 6 | E9: =AVERAGEIF(Dataset!G:G,'Task-Solution'!C9,Dataset!R:R) -> 1271478.6 | H9: =ROUNDDOWN((TODAY()-Dataset!J9)/365,0) -> 36 | I9: =_xlfn.XLOOKUP(H9,'Age Range'!A:A,'Age Range'!B:B) -> 30-39
A10: Highest Salary | C10: Capability Development | D10: =COUNTIF(Dataset!G:G,'Task-Solution'!C10) -> 2 | E10: =AVERAGEIF(Dataset!G:G,'Task-Solution'!C10,Dataset!R:R) -> 2061954.9 | H10: =ROUNDDOWN((TODAY()-Dataset!J10)/365,0) -> 38 | I10: =_xlfn.XLOOKUP(H10,'Age Range'!A:A,'Age Range'!B:B) -> 30-39
A11: =MAX(Dataset!R:R) -> 4000000 | C11: Human Resources | D11: =COUNTIF(Dataset!G:G,'Task-Solution'!C11) -> 4 | E11: =AVERAGEIF(Dataset!G:G,'Task-Solution'!C11,Dataset!R:R) -> 1414587.7 | H11: =ROUNDDOWN((TODAY()-Dataset!J11)/365,0) -> 30 | I11: =_xlfn.XLOOKUP(H11,'Age Range'!A:A,'Age Range'!B:B) -> 30-39
C12: R&C | D12: =COUNTIF(Dataset!G:G,'Task-Solution'!C12) -> 2 | E12: =AVERAGEIF(Dataset!G:G,'Task-Solution'!C12,Dataset!R:R) -> 686108.79 | H12: =ROUNDDOWN((TODAY()-Dataset!J12)/365,0) -> 37 | I12: =_xlfn.XLOOKUP(H12,'Age Range'!A:A,'Age Range'!B:B) -> 30-39
A13: Lowest Salary | C13: Communications | D13: =COUNTIF(Dataset!G:G,'Task-Solution'!C13) -> 1 | E13: =AVERAGEIF(Dataset!G:G,'Task-Solution'!C13,Dataset!R:R) -> 705478.89 | H13: =ROUNDDOWN((TODAY()-Dataset!J13)/365,0) -> 36 | I13: =_xlfn.XLOOKUP(H13,'Age Range'!A:A,'Age Range'!B:B) -> 30-39
A14: =MIN(Dataset!R:R) -> 101581.2 | C14: Legal | D14: =COUNTIF(Dataset!G:G,'Task-Solution'!C14) -> 2 | E14: =AVERAGEIF(Dataset!G:G,'Task-Solution'!C14,Dataset!R:R) -> 2369397.2 | H14: =ROUNDDOWN((TODAY()-Dataset!J14)/365,0) -> 35 | I14: =_xlfn.XLOOKUP(H14,'Age Range'!A:A,'Age Range'!B:B) -> 30-39
C15: Md'S Office | D15: =COUNTIF(Dataset!G:G,'Task-Solution'!C15) -> 1 | E15: =AVERAGEIF(Dataset!G:G,'Task-Solution'!C15,Dataset!R:R) -> 508980 | H15: =ROUNDDOWN((TODAY()-Dataset!J15)/365,0) -> 29 | I15: =_xlfn.XLOOKUP(H15,'Age Range'!A:A,'Age Range'!B:B) -> 20-29
A16: Performance Score >80 | H16: =ROUNDDOWN((TODAY()-Dataset!J16)/365,0) -> 40 | I16: =_xlfn.XLOOKUP(H16,'Age Range'!A:A,'Age Range'!B:B) -> 40-49
A17: =COUNTIF(Dataset!S:S,">80") -> 66 | H17: =ROUNDDOWN((TODAY()-Dataset!J17)/365,0) -> 44 | I17: =_xlfn.XLOOKUP(H17,'Age Range'!A:A,'Age Range'!B:B) -> 40-49
H18: =ROUNDDOWN((TODAY()-Dataset!J18)/365,0) -> 33 | I18: =_xlfn.XLOOKUP(H18,'Age Range'!A:A,'Age Range'!B:B) -> 30-39
A19: Average Tenure of Employees | H19: =ROUNDDOWN((TODAY()-Dataset!J19)/365,0) -> 35 | I19: =_xlfn.XLOOKUP(H19,'Age Range'!A:A,'Age Range'!B:B) -> 30-39
A20: =AVERAGE(Dataset!N:N) -> 12.079498 | H20: =ROUNDDOWN((TODAY()-Dataset!J20)/365,0) -> 29 | I20: =_xlfn.XLOOKUP(H20,'Age Range'!A:A,'Age Range'!B:B) -> 20-29
